Workbook

Sheet PPID Project
A1: S. No. | B1: Project Code | C1: Project Name | D1: Vertical | E1: Project Lead | F1: SPOC | G1: Project Status | H1: Project Start Date (DD/MM/YYYY) | I1: Project End Date (DD/MM/YYYY) | J1: Revised End Date (DD/MM/YYYY) | K1: Client/Department | L1: Client/Ministry | M1: Client Type | N1: Sector/Domain | O1: Sub-Domain | P1: Geographical Coverage | Q1: Nature of Project (TPA/TPE/TPI/TPQA/PMU/PMC/Capacity Building/Impact Assessment) | R1: Internal Stakeholders | S1: External Stakeholders | T1: Project Brief/Objective | U1: Outcomes achieved/Impact created | V1: Award Type | W1: Work Order Value | X1: Proposal | Y1: Project Charter | Z1: Financial Charter | AA1: Bid Filing Documents | AB1: Project Code Generation Requisition Form | AC1: Work Order | AD1: Work orders issued to external stakeholders (if any) | AE1: Work Order Extension | AF1: Revised Financial Charter | AG1: Final Report | AH1: Completion Certificate | AI1: Invoices | AJ1: NOC from Finance Department | AK1: Project Closure Report
A2: 1 | B2: PB00001 | C2: Niti Study | J2: =VLOOKUP(Table1[[#This Row],[Project Code]],'[6]Combined Nov''25'!$E:$O,10,FALSE) -> #N/A | K2: =VLOOKUP(Table1[[#This Row],[Project Code]],'[6]Combined Nov''25'!$E:$K,6,FALSE) -> #N/A | M2: Ministry | N2: =VLOOKUP(Table1[[#This Row],[Project Code]],'[6]Combined Nov''25'!$E:$K,7,FALSE) -> #N/A | O2: Others | P2: Pan India | Q2: Others | T2: =VLOOKUP(Table1[[#This Row],[Project Code]],'[6]Combined Nov''25'!$E:$P,12,FALSE) -> #N/A | U2: #N/A | V2: #N/A | W2: #N/A | X2: No | Y2: No | Z2: No | AA2: No | AB2: No | AC2: No | AD2: No | AE2: No | AF2: No | AG2: No | AH2: No | AI2: No | AJ2: No | AK2: No
A3: 2 | B3: PB00002 | C3: Census of Traders | J3: =VLOOKUP(Table1[[#This Row],[Project Code]],'[6]Combined Nov''25'!$E:$O,10,FALSE) -> #N/A | K3: Department for Promotion of Industry and Internal Trade | L3: Ministry of Commerce and Industry | M3: Ministry | N3: =VLOOKUP(Table1[[#This Row],[Project Code]],'[6]Combined Nov''25'!$E:$K,7,FALSE) -> #N/A | O3: Financial Mgmt, Policy Analysis & Research | P3: Pan India | Q3: Capacity building & Impact Assessment | T3: =VLOOKUP(Table1[[#This Row],[Project Code]],'[6]Combined Nov''25'!$E:$P,12,FALSE) -> #N/A | U3: #N/A | V3: #N/A | W3: #N/A | X3: No | Y3: Yes | Z3: Yes | AA3: No | AB3: No | AC3: Yes | AD3: No | AE3: No | AF3: No | AG3: No | AH3: No | AI3: No | AJ3: No | AK3: No
A4: 3 | B4: PB00003 | C4: E-Commerce Compliance | J4: =VLOOKUP(Table1[[#This Row],[Project Code]],'[6]Combined Nov''25'!$E:$O,10,FALSE) -> #N/A | K4: =VLOOKUP(Table1[[#This Row],[Project Code]],'[6]Combined Nov''25'!$E:$K,6,FALSE) -> #N/A | M4: Ministry | N4: =VLOOKUP(Table1[[#This Row],[Project Code]],'[6]Combined Nov''25'!$E:$K,7,FALSE) -> #N/A | O4: Others | P4: Pan India | Q4: Others | T4: =VLOOKUP(Table1[[#This Row],[Project Code]],'[6]Combined Nov''25'!$E:$P,12,FALSE) -> #N/A | U4: #N/A | V4: #N/A | W4: #N/A | X4: No | Y4: No | Z4: No | AA4: No | AB4: No | AC4: No | AD4: No | AE4: No | AF4: No | AG4: No | AH4: No | AI4: No | AJ4: No | AK4: No
A5: 4 | B5: PB00004 | C5: TPI of buses, depots, workshops & stations of UP | J5: =VLOOKUP(Table1[[#This Row],[Project Code]],'[6]Combined Nov''25'!$E:$O,10,FALSE) -> #N/A | K5: Uttar Pradesh State Road Transport Corporation (UPSRTC) | L5: Government of Uttar Pradesh | M5: 0 | N5: =VLOOKUP(Table1[[#This Row],[Project Code]],'[6]Combined Nov''25'!$E:$K,7,FALSE) -> #N/A | O5: Structural & Utilities Management | P5: Uttar Pradesh | Q5: TPI/TPA/TPE/TPQA | T5: =VLOOKUP(Table1[[#This Row],[Project Code]],'[6]Combined Nov''25'!$E:$P,12,FALSE) -> #N/A | U5: #N/A | V5: #N/A | W5: #N/A | X5: No | Y5: No | Z5: No | AA5: No | AB5: No | AC5: No | AD5: No | AE5: No | AF5: No | AG5: No | AH5: No | AI5: No | AJ5: No | AK5: No
A6: 5 | B6: PB00011 | C6: Sarpanch Samvaad | J6: =VLOOKUP(Table1[[#This Row],[Project Code]],'[6]Combined Nov''25'!$E:$O,10,FALSE) -> #N/A | K6: =VLOOKUP(Table1[[#This Row],[Project Code]],'[6]Combined Nov''25'!$E:$K,6,FALSE) -> #N/A | M6: 0 | N6: =VLOOKUP(Table1[[#This Row],[Project Code]],'[6]Combined Nov''25'!$E:$K,7,FALSE) -> #N/A | O6: Social Welfare, Education & Skill Development | P6: Pan India | Q6: Capacity building & Impact Assessment | T6: =VLOOKUP(Table1[[#This Row],[Project Code]],'[6]Combined Nov''25'!$E:$P,12,FALSE) -> #N/A | U6: #N/A | V6: #N/A | W6: #N/A | X6: No | Y6: No | Z6: No | AA6: No | AB6: No | AC6: No | AD6: No | AE6: No | AF6: No | AG6: No | AH6: No | AI6: No | AJ6: No | AK6: No
A7: 6 | B7: PB00012 | C7: Nashik | D7: PF, P&S | E7: Karan Singh | G7: =VLOOKUP(Table1[[#This Row],[Project Code]],[1]Combined!$E:$I,5,FALSE) -> Ongoing | H7: =VLOOKUP(Table1[[#This Row],[Project Code]],'[2]Combined '!$E:$N,8,FALSE) -> 45075 | K7: Nashik Municipal Corporation | L7: Government of Maharashtra | M7: State Govt. | N7: Sanitaion, Education and Skill development | O7: Water & Sanitation | P7: Maharashtra | Q7: Others | T7: QCI has been engaged by Nashik Municipal Corporation for one of its kind Quality City initiative aiming for situational analysis of different sectors and provide on ground implementation support for several initiatives. | U7: Under the Swachhta Hi Seva Hai initiative, a comprehensive community outreach program was successfully conducted, encompassing a cleanliness drive across four strategic locations and tree plantation at two sites, promoting environmental sustainability. Additionally, an inter-divisional cricket match among Solid Waste Management divisions fostered teamwork and camaraderie, reinforcing the initiative's mission to enhance community engagement, cleanliness, and eco-friendliness. | V7: 0 | W7: N/A | X7: Yes | Z7: Yes | AA7: No | AB7: No | AC7: Yes | AD7: No | AE7: No | AF7: No | AG7: No | AH7: No | AI7: No | AJ7: No | AK7: No
A8: 7 | B8: PB00013 | C8: Trade Surveillance- Leather | J8: =VLOOKUP(Table1[[#This Row],[Project Code]],'[6]Combined Nov''25'!$E:$O,10,FALSE) -> #N/A | K8: =VLOOKUP(Table1[[#This Row],[Project Code]],'[6]Combined Nov''25'!$E:$K,6,FALSE) -> #N/A | M8: 0 | N8: =VLOOKUP(Table1[[#This Row],[Project Code]],'[6]Combined Nov''25'!$E:$K,7,FALSE) -> #N/A | O8: Agriculture, Food Processing & Supply Chain | P8: Pan India | Q8: TPI/TPA/TPE/TPQA | T8: =VLOOKUP(Table1[[#This Row],[Project Code]],'[6]Combined Nov''25'!$E:$P,12,FALSE) -> #N/A | U8: #N/A | V8: #N/A | W8: #N/A | X8: No | Z8: Yes | AA8: No | AB8: Yes | AC8: Yes | AD8: No | AE8: No | AF8: No | AG8: No | AH8: No | AI8: No | AJ8: No | AK8: No
A9: 8 | B9: PB00014 | C9: Quality Assessment of Compressed Bio Gas | D9: T,C,W & E | E9: Dinesh Bhat | G9: Fully Closed | H9: =VLOOKUP(Table1[[#This Row],[Project Code]],'[2]Combined '!$E:$N,8,FALSE) -> 45087 | K9: Banaskantha District Co-op. Milk Producers' Union Ltd. | L9: Cooperative | M9: Cooperative | N9: Bio energy | O9: Mining & Metallurgy | P9: Gujarat | Q9: TPI/TPA/TPE/TPQA | T9: To assess the quality of Biogas getting produced at their Biogas plant located in Palanpur | U9: 1. The Quality Assessment of Biogas marked a pivotal advancement in ensuring the quality of biogas production. The pilot project established a standardized methodology for evaluating biogas quality, with rigorous testing confirming compliance with IS 16087 standards. Sampling and analysis by NABL-accredited laboratories validated high methane content and low impurities. | V9: Nomination | X9: Yes | Y9: No | Z9: No | AA9: No | AB9: No | AC9: Yes | AD9: No | AE9: No | AF9: No | AG9: No | AH9: No | AI9: No | AJ9: No | AK9: No
A10: 9 | B10: PB00015 | C10: Dipstick Assessment for receipt of free grains under PMGKAY | D10: F & H | E10: Ankita Garg | G10: Fully Closed | H10: =VLOOKUP(Table1[[#This Row],[Project Code]],'[2]Combined '!$E:$N,8,FALSE) -> 45055 | K10: =VLOOKUP(Table1[[#This Row],[Project Code]],'[6]Combined Nov''25'!$E:$K,6,FALSE) -> DFPD | L10: Department of Food and Public Distribution | M10: Ministry | N10: Food | O10: Agriculture, Food Processing & Supply Chain | P10: Pan India | Q10: TPI/TPA/TPE/TPQA | T10: Conduct a study about the receipt of free-of-cost food grains under the scheme PMGKAY and beneficiary satisfaction through an on-ground survey. | U10: More than the required feedbacks were collected (nearly 104%) by QCI from across the Indian States/Uts barring six States/UTs namely Odisha, Lakshadweep, Mizoram, Manipur, Chandigarh and Puducherry as either we did not received support from the State or Direct Benefit Transfer (DBT) is applicable or due to civic unrest. The overall result come out to be positive. | V10: Nomination | X10: Yes | Y10: Yes | Z10: No | AA10: No | AB10: No | AC10: No | AD10: Yes | AE10: No | AF10: No | AG10: No | AH10: No | AI10: No | AJ10: No | AK10: No
A11: 10 | B11: PB00016 | C11: TPI of residential building under Rajasthan Housing Board | J11: =VLOOKUP(Table1[[#This Row],[Project Code]],'[6]Combined Nov''25'!$E:$O,10,FALSE) -> #N/A | K11: =VLOOKUP(Table1[[#This Row],[Project Code]],'[6]Combined Nov''25'!$E:$K,6,FALSE) -> #N/A | M11: 0 | N11: =VLOOKUP(Table1[[#This Row],[Project Code]],'[6]Combined Nov''25'!$E:$K,7,FALSE) -> #N/A | O11: Structural & Utilities Management | P11: Rajasthan | Q11: TPI/TPA/TPE/TPQA | T11: =VLOOKUP(Table1[[#This Row],[Project Code]],'[6]Combined Nov''25'!$E:$P,12,FALSE) -> #N/A | U11: #N/A | V11: #N/A | X11: Yes | Y11: No | Z11: Yes | AA11: No | AB11: Yes | AC11: Yes | AD11: No | AE11: No | AF11: No | AG11: No | AH11: No | AI11: No | AJ11: No | AK11: No
A12: 11 | B12: PB00017 | C12: SILF | D12: Infra | E12: Shailja Devgan | G12: Fully Closed | H12: =VLOOKUP(Table1[[#This Row],[Project Code]],'[2]Combined '!$E:$N,8,FALSE) -> 44938 | K12: =VLOOKUP(Table1[[#This Row],[Project Code]],'[6]Combined Nov''25'!$E:$K,6,FALSE) -> SILF | L12: Sasakawa-India Leprosy Foundation. | M12: Non-Profit Organisation | N12: Social Impact | O12: Social Welfare, Education & Skill Development | P12: Pan India | Q12: Capacity building & Impact Assessment | T12: To conduct an impact evaluation of the livelihoods project in the Champa district of Chhattisgarh which will analyze the impact of the project on the lives of the beneficiaries and their family members, any substantive change in their socio-economic standing. | U12: Narrative analysis questionniare been developed and interviews conducted for beneficiaries who received funds from SILF to understand the in-depth impact. The final report with analysis has been submitted. | V12: 0 | W12: 246400 | X12: Yes | Y12: No | Z12: Yes | AA12: No | AB12: No | AC12: No | AD12: No | AE12: No | AF12: No | AG12: Yes | AH12: No | AI12: No | AJ12: No | AK12: No
A13: 12 | B13: PB00018 | C13: Culture_National Library_2024 | D13: T,C,W & E | E13: Prakhar Joshi | G13: Fully Closed | H13: =VLOOKUP(Table1[[#This Row],[Project Code]],'[2]Combined '!$E:$N,8,FALSE) -> 45383 | K13: =VLOOKUP(Table1[[#This Row],[Project Code]],'[6]Combined Nov''25'!$E:$K,6,FALSE) -> Ministry of Culture | L13: Ministry of Culture | M13: Ministry | N13: Arts, Culture & Heritage | O13: Arts, Culture & Tourism | P13: Pan India | Q13: Capacity building & Impact Assessment | T13: The National Library functions as a Subordinative Office of the Ministry of Culture, Government of India. As part of Phase-1 Study of Organizations & Central Sector Schemes of the Ministry of Culture, QCI had outlined broad recommendations for the National Library. | U13: Restoration of 25% of the workforce at the National Library Designing structure of a proposed digital department that can effectively help preserve 2+ million books Developed detailed KRAs of 500+ posts at the National Library | V13: Nomination | W13: 0 | Y13: No | Z13: No | AA13: No | AB13: No | AC13: Yes | AD13: No | AE13: No | AF13: No | AG13: No | AH13: No | AI13: No | AJ13: No | AK13: No
A14: 13 | B14: PB00019 | C14: Assessment, Capacity Building & Certification of SST | D14: T,C,W & E | E14: Dinesh Bhat | G14: =VLOOKUP(Table1[[#This Row],[Project Code]],[1]Combined!$E:$I,5,FALSE) -> Ongoing | H14: =VLOOKUP(Table1[[#This Row],[Project Code]],'[2]Combined '!$E:$N,8,FALSE) -> 45385 | K14: =VLOOKUP(Table1[[#This Row],[Project Code]],'[6]Combined Nov''25'!$E:$K,6,FALSE) -> Shri Somnath Trust | L14: Shri Somnath Trust | M14: Independent Body | N14: Tourism | O14: Arts, Culture & Tourism | P14: Gujarat | Q14: Capacity building & Impact Assessment | T14: The National Library then requested QCI to undertake a detailed review of its existing manpower, structure and governance models, and activities and make suggestions for changes. QCI reviewed the institution in detail: including their current recruitment rules, Staff Inspection Unit Report, and other previous reports highlighting human resource related issues of the National Library, governance, structure, objective and mandate. In order to understand the landscape further, QCI also studied organizational structures and hierarchy models of leading global libraries. | U14: The impact extends beyond technical compliance. Enhanced biogas quality supports national clean energy goals, reduces dependence on fossil fuels, and mitigates greenhouse gas emissions. It also leads to improved energy efficiency, lower operational costs, and strengthened sustainability efforts | V14: Nomination | W14: 0 | Y14: No | Z14: No | AA14: No | AB14: No | AC14: No | AD14: No | AE14: No | AF14: No | AG14: No | AH14: No | AI14: No | AJ14: No | AK14: No
A15: 14 | B15: PP00001 | C15: Third Party Sampling, Testing & Analysis of Coal | D15: NR | E15: Abhishek Mazumdar | G15: =VLOOKUP(Table1[[#This Row],[Project Code]],[1]Combined!$E:$I,5,FALSE) -> Ongoing | H15: =VLOOKUP(Table1[[#This Row],[Project Code]],'[2]Combined '!$E:$N,8,FALSE) -> 42881 | K15: =VLOOKUP(Table1[[#This Row],[Project Code]],'[6]Combined Nov''25'!$E:$K,6,FALSE) -> Coal India Limited | L15: Coal India Limited | M15: PSU | N15: Coal | O15: Mining & Metallurgy | P15: Pan India | Q15: TPI/TPA/TPE/TPQA | T15: Collection, preparation and analysis of coal at loading points for non- power consumers and power sector consumers | U15: QCI has executed around 4,770+ tripartite agreements among the coal companies and 370+ coal consumers for facilitating the Third Party Sampling of coal (TPS). QCI has commenced it’s operations at 320+ loading/dispatch points across the CIL subsidiaries. More than 707.27 Million Metric Tonnes of coal has been sampled since the inception and analysis results submitted within the 15 working days as per the service level agreement. | V15: Nomination | W15: 0 | Y15: No | Z15: No | AA15: No | AB15: No | AC15: No | AD15: No | AE15: No | AF15: No | AG15: No | AH15: No | AI15: No | AJ15: No | AK15: No
A16: 15 | B16: PP00002 | C16: SBM ODF, ODF+, ODF++ | J16: =VLOOKUP(Table1[[#This Row],[Project Code]],'[6]Combined Nov''25'!$E:$O,10,FALSE) -> #N/A | K16: =VLOOKUP(Table1[[#This Row],[Project Code]],'[6]Combined Nov''25'!$E:$K,6,FALSE) -> #N/A | L16: Ministry of Housing and Urban Affairs | M16: Ministry | N16: =VLOOKUP(Table1[[#This Row],[Project Code]],'[6]Combined Nov''25'!$E:$K,7,FALSE) -> #N/A | O16: Water & Sanitation | P16: Pan India | Q16: TPI/TPA/TPE/TPQA | T16: =VLOOKUP(Table1[[#This Row],[Project Code]],'[6]Combined Nov''25'!$E:$P,12,FALSE) -> #N/A | U16: #N/A | V16: #N/A | W16: #N/A | X16: No | Y16: No | Z16: Yes | AA16: No | AB16: Yes | AC16: Yes | AD16: No | AE16: No | AF16: No | AG16: No | AH16: No | AI16: No | AJ16: No | AK16: No
A17: 16 | B17: PP00003 | C17: MoUD - Star Rating | J17: =VLOOKUP(Table1[[#This Row],[Project Code]],'[6]Combined Nov''25'!$E:$O,10,FALSE) -> #N/A | K17: =VLOOKUP(Table1[[#This Row],[Project Code]],'[6]Combined Nov''25'!$E:$K,6,FALSE) -> #N/A | L17: Ministry of Housing and Urban Affairs | M17: Ministry | N17: =VLOOKUP(Table1[[#This Row],[Project Code]],'[6]Combined Nov''25'!$E:$K,7,FALSE) -> #N/A | O17: Water & Sanitation | P17: Pan India | Q17: TPI/TPA/TPE/TPQA | T17: =VLOOKUP(Table1[[#This Row],[Project Code]],'[6]Combined Nov''25'!$E:$P,12,FALSE) -> #N/A | U17: #N/A | V17: #N/A | W17: #N/A | Y17: No | Z17: No | AA17: No | AB17: No | AC17: No | AD17: No | AE17: No | AF17: No | AG17: No | AH17: No | AI17: No | AJ17: No | AK17: No
A18: 17 | B18: PP00004 | C18: TPI of 97 Ganga Towns | J18: =VLOOKUP(Table1[[#This Row],[Project Code]],'[6]Combined Nov''25'!$E:$O,10,FALSE) -> #N/A | K18: =VLOOKUP(Table1[[#This Row],[Project Code]],'[6]Combined Nov''25'!$E:$K,6,FALSE) -> #N/A | L18: Ministry of Housing and Urban Affairs | M18: Ministry | N18: =VLOOKUP(Table1[[#This Row],[Project Code]],'[6]Combined Nov''25'!$E:$K,7,FALSE) -> #N/A | O18: Water & Sanitation | P18: Pan India | Q18: TPI/TPA/TPE/TPQA | T18: =VLOOKUP(Table1[[#This Row],[Project Code]],'[6]Combined Nov''25'!$E:$P,12,FALSE) -> #N/A | U18: #N/A | V18: #N/A | W18: #N/A | Y18: No | Z18: No | AA18: No | AB18: No | AC18: No | AD18: No | AE18: No | AF18: No | AG18: No | AH18: No | AI18: No | AJ18: No | AK18: No
A19: 18 | B19: PP00005 | C19: IDFOI Assessment | J19: =VLOOKUP(Table1[[#This Row],[Project Code]],'[6]Combined Nov''25'!$E:$O,10,FALSE) -> #N/A | K19: IBF-OI | L19: Govt Body (Not for Profit) | M19: Ministry | N19: =VLOOKUP(Table1[[#This Row],[Project Code]],'[6]Combined Nov''25'!$E:$K,7,FALSE) -> #N/A | O19: Financial Mgmt, Policy Analysis & Research | P19: Pan India | Q19: TPI/TPA/TPE/TPQA | T19: =VLOOKUP(Table1[[#This Row],[Project Code]],'[6]Combined Nov''25'!$E:$P,12,FALSE) -> #N/A | U19: #N/A | V19: #N/A | W19: #N/A | Y19: No | Z19: No | AA19: No | AB19: No | AC19: No | AD19: No | AE19: No | AF19: No | AG19: No | AH19: No | AI19: No | AJ19: No | AK19: No
A20: 19 | B20: PP00006 | C20: Swachh RO | J20: =VLOOKUP(Table1[[#This Row],[Project Code]],'[6]Combined Nov''25'!$E:$O,10,FALSE) -> #N/A | K20: =VLOOKUP(Table1[[#This Row],[Project Code]],'[6]Combined Nov''25'!$E:$K,6,FALSE) -> #N/A | L20: HPCL | M20: PSU | N20: =VLOOKUP(Table1[[#This Row],[Project Code]],'[6]Combined Nov''25'!$E:$K,7,FALSE) -> #N/A | O20: Water & Sanitation | P20: Pan India | Q20: TPI/TPA/TPE/TPQA | T20: =VLOOKUP(Table1[[#This Row],[Project Code]],'[6]Combined Nov''25'!$E:$P,12,FALSE) -> #N/A | U20: #N/A | V20: #N/A | W20: #N/A | X20: No | Y20: No | Z20: No | AA20: No | AB20: No | AC20: No | AD20: No | AE20: No | AF20: No | AG20: No | AH20: No | AI20: No | AJ20: No | AK20: No
A21: 20 | B21: PP00007 | C21: Madhya Pradesh PIU | J21: =VLOOKUP(Table1[[#This Row],[Project Code]],'[6]Combined Nov''25'!$E:$O,10,FALSE) -> #N/A | K21: =VLOOKUP(Table1[[#This Row],[Project Code]],'[6]Combined Nov''25'!$E:$K,6,FALSE) -> #N/A | L21: Government of Madhya Pradesh | M21: State Govt. | N21: =VLOOKUP(Table1[[#This Row],[Project Code]],'[6]Combined Nov''25'!$E:$K,7,FALSE) -> #N/A | O21: Water & Sanitation | P21: Madhya Pradesh | Q21: Capacity building & Impact Assessment | T21: =VLOOKUP(Table1[[#This Row],[Project Code]],'[6]Combined Nov''25'!$E:$P,12,FALSE) -> #N/A | U21: #N/A | V21: #N/A | W21: #N/A | X21: No | Y21: Yes | Z21: No | AA21: No | AB21: No | AC21: No | AD21: No | AE21: No | AF21: No | AG21: No | AH21: No | AI21: No | AJ21: No | AK21: No
A22: 21 | B22: PP00008 | C22: Gwalior PIU | J22: =VLOOKUP(Table1[[#This Row],[Project Code]],'[6]Combined Nov''25'!$E:$O,10,FALSE) -> #N/A | K22: Municipal Corporation of Gwalior | L22: Government of Madhya Pradesh | M22: State Govt. | N22: =VLOOKUP(Table1[[#This Row],[Project Code]],'[6]Combined Nov''25'!$E:$K,7,FALSE) -> #N/A | O22: Water & Sanitation | P22: Madhya Pradesh | Q22: Capacity building & Impact Assessment | T22: =VLOOKUP(Table1[[#This Row],[Project Code]],'[6]Combined Nov''25'!$E:$P,12,FALSE) -> #N/A | U22: #N/A | V22: #N/A | W22: #N/A | X22: Yes | Y22: Yes | Z22: Yes | AA22: No | AB22: Yes | AC22: Yes | AD22: Yes | AE22: No | AF22: No | AG22: Yes | AH22: No | AI22: No | AJ22: No | AK22: No
A23: 22 | B23: PP00009 | C23: Swastha Pradesh Swachh Pradesh | J23: =VLOOKUP(Table1[[#This Row],[Project Code]],'[6]Combined Nov''25'!$E:$O,10,FALSE) -> #N/A | K23: =VLOOKUP(Table1[[#This Row],[Project Code]],'[6]Combined Nov''25'!$E:$K,6,FALSE) -> #N/A | L23: Government of Madhya Pradesh | M23: State Govt. | N23: =VLOOKUP(Table1[[#This Row],[Project Code]],'[6]Combined Nov''25'!$E:$K,7,FALSE) -> #N/A | O23: Water & Sanitation | P23: Madhya Pradesh | Q23: TPI/TPA/TPE/TPQA | T23: =VLOOKUP(Table1[[#This Row],[Project Code]],'[6]Combined Nov''25'!$E:$P,12,FALSE) -> #N/A | U23: #N/A | V23: #N/A | W23: #N/A | X23: No | Y23: No | Z23: No | AA23: No | AB23: No | AC23: No | AD23: No | AE23: No | AF23: No | AG23: No | AH23: No | AI23: No | AJ23: No | AK23: No
A24: 23 | B24: PP00010 | C24: Delhi Toilet Survey | J24: =VLOOKUP(Table1[[#This Row],[Project Code]],'[6]Combined Nov''25'!$E:$O,10,FALSE) -> #N/A | K24: =VLOOKUP(Table1[[#This Row],[Project Code]],'[6]Combined Nov''25'!$E:$K,6,FALSE) -> #N/A | L24: Ministry of Housing and Urban Affairs | M24: Ministry | N24: =VLOOKUP(Table1[[#This Row],[Project Code]],'[6]Combined Nov''25'!$E:$K,7,FALSE) -> #N/A | O24: Water & Sanitation | P24: NCT of Delhi | Q24: TPI/TPA/TPE/TPQA | T24: =VLOOKUP(Table1[[#This Row],[Project Code]],'[6]Combined Nov''25'!$E:$P,12,FALSE) -> #N/A | U24: #N/A | V24: #N/A | W24: #N/A | X24: No | Y24: No | Z24: Yes | AA24: Yes | AB24: Yes | AC24: Yes | AD24: No | AE24: No | AF24: No | AG24: No | AH24: No | AI24: No | AJ24: No | AK24: No
A25: 24 | B25: PP00011 | C25: Google Toilet Mapping | J25: =VLOOKUP(Table1[[#This Row],[Project Code]],'[6]Combined Nov''25'!$E:$O,10,FALSE) -> #N/A | K25: =VLOOKUP(Table1[[#This Row],[Project Code]],'[6]Combined Nov''25'!$E:$K,6,FALSE) -> #N/A | L25: Ministry of Housing and Urban Affairs | M25: Ministry | N25: =VLOOKUP(Table1[[#This Row],[Project Code]],'[6]Combined Nov''25'!$E:$K,7,FALSE) -> #N/A | O25: Water & Sanitation | P25: Pan India | Q25: TPI/TPA/TPE/TPQA | T25: =VLOOKUP(Table1[[#This Row],[Project Code]],'[6]Combined Nov''25'!$E:$P,12,FALSE) -> #N/A | U25: #N/A | V25: #N/A | W25: #N/A | X25: Yes | Y25: Yes | Z25: Yes | AA25: No | AB25: No | AC25: Yes | AD25: Yes | AE25: No | AF25: No | AG25: Yes | AH25: No | AI25: No | AJ25: No | AK25: No
A26: 25 | B26: PP00012 | C26: SBM Jharkhand | J26: =VLOOKUP(Table1[[#This Row],[Project Code]],'[6]Combined Nov''25'!$E:$O,10,FALSE) -> #N/A | K26: =VLOOKUP(Table1[[#This Row],[Project Code]],'[6]Combined Nov''25'!$E:$K,6,FALSE) -> #N/A | L26: Government of Jharkhand | M26: State Govt. | N26: =VLOOKUP(Table1[[#This Row],[Project Code]],'[6]Combined Nov''25'!$E:$K,7,FALSE) -> #N/A | O26: Water & Sanitation | P26: Jharkhand | Q26: TPI/TPA/TPE/TPQA | T26: =VLOOKUP(Table1[[#This Row],[Project Code]],'[6]Combined Nov''25'!$E:$P,12,FALSE) -> #N/A | U26: #N/A | V26: #N/A | W26: #N/A | X26: Yes | Y26: Yes | Z26: Yes | AA26: No | AB26: No | AC26: Yes | AD26: No | AE26: No | AF26: No | AG26: Yes | AH26: No | AI26: No | AJ26: No | AK26: No
A27: 26 | B27: PP00013 | C27: Swachh Rail 2018 | J27: =VLOOKUP(Table1[[#This Row],[Project Code]],'[6]Combined Nov''25'!$E:$O,10,FALSE) -> #N/A | K27: =VLOOKUP(Table1[[#This Row],[Project Code]],'[6]Combined Nov''25'!$E:$K,6,FALSE) -> #N/A | L27: Ministry of Railways | M27: Ministry | N27: =VLOOKUP(Table1[[#This Row],[Project Code]],'[6]Combined Nov''25'!$E:$K,7,FALSE) -> #N/A | O27: Water & Sanitation | P27: Pan India | Q27: TPI/TPA/TPE/TPQA | T27: =VLOOKUP(Table1[[#This Row],[Project Code]],'[6]Combined Nov''25'!$E:$P,12,FALSE) -> #N/A | U27: #N/A | V27: #N/A | W27: #N/A | X27: No | Y27: No | Z27: No | AA27: No | AB27: No | AC27: Yes | AD27: No | AE27: No | AF27: No | AG27: No | AH27: No | AI27: No | AJ27: No | AK27: No
A28: 27 | B28: PP00014 | C28: SBM Telangana | J28: =VLOOKUP(Table1[[#This Row],[Project Code]],'[6]Combined Nov''25'!$E:$O,10,FALSE) -> #N/A | K28: =VLOOKUP(Table1[[#This Row],[Project Code]],'[6]Combined Nov''25'!$E:$K,6,FALSE) -> #N/A | L28: Government of Telangana | M28: State Govt. | N28: =VLOOKUP(Table1[[#This Row],[Project Code]],'[6]Combined Nov''25'!$E:$K,7,FALSE) -> #N/A | O28: Water & Sanitation | P28: Telangana | Q28: TPI/TPA/TPE/TPQA | T28: =VLOOKUP(Table1[[#This Row],[Project Code]],'[6]Combined Nov''25'!$E:$P,12,FALSE) -> #N/A | U28: #N/A | V28: #N/A | W28: #N/A | X28: No | Y28: No | Z28: No | AA28: No | AB28: No | AC28: No | AD28: No | AE28: No | AF28: No | AG28: No | AH28: No | AI28: No | AJ28: No | AK28: No
A29: 28 | B29: PP00015 | C29: SBM Gujarat Yatradham | J29: =VLOOKUP(Table1[[#This Row],[Project Code]],'[6]Combined Nov''25'!$E:$O,10,FALSE) -> #N/A | K29: Tourism Corporation of Gujarat Limited | L29: Government of Gujarat | M29: State Govt. | N29: =VLOOKUP(Table1[[#This Row],[Project Code]],'[6]Combined Nov''25'!$E:$K,7,FALSE) -> #N/A | O29: Water & Sanitation | P29: Gujarat | Q29: TPI/TPA/TPE/TPQA | T29: =VLOOKUP(Table1[[#This Row],[Project Code]],'[6]Combined Nov''25'!$E:$P,12,FALSE) -> #N/A | U29: #N/A | V29: #N/A | W29: #N/A | X29: No | Y29: No | Z29: No | AA29: No | AB29: No | AC29: No | AD29: No | AE29: No | AF29: No | AG29: No | AH29: No | AI29: No | AJ29: No | AK29: No
A30: 29 | B30: PP00016 | C30: SBM Gujarat Tourism | J30: =VLOOKUP(Table1[[#This Row],[Project Code]],'[6]Combined Nov''25'!$E:$O,10,FALSE) -> #N/A | K30: Tourism Corporation of Gujarat Limited | L30: Government of Gujarat | M30: State Govt. | N30: =VLOOKUP(Table1[[#This Row],[Project Code]],'[6]Combined Nov''25'!$E:$K,7,FALSE) -> #N/A | O30: Water & Sanitation | P30: Gujarat | Q30: TPI/TPA/TPE/TPQA | T30: =VLOOKUP(Table1[[#This Row],[Project Code]],'[6]Combined Nov''25'!$E:$P,12,FALSE) -> #N/A | U30: #N/A | V30: #N/A | W30: #N/A | X30: No | Y30: No | Z30: No | AA30: No | AB30: No | AC30: No | AD30: No | AE30: No | AF30: No | AG30: No | AH30: No | AI30: No | AJ30: No | AK30: No
A31: 30 | B31: PP00017 | C31: Statue of Unity | J31: =VLOOKUP(Table1[[#This Row],[Project Code]],'[6]Combined Nov''25'!$E:$O,10,FALSE) -> #N/A | K31: Tourism Corporation of Gujarat Limited | L31: Government of Gujarat | M31: State Govt. | N31: =VLOOKUP(Table1[[#This Row],[Project Code]],'[6]Combined Nov''25'!$E:$K,7,FALSE) -> #N/A | O31: Structural & Utilities Management | P31: Gujarat | Q31: TPI/TPA/TPE/TPQA | T31: =VLOOKUP(Table1[[#This Row],[Project Code]],'[6]Combined Nov''25'!$E:$P,12,FALSE) -> #N/A | U31: #N/A | V31: #N/A | W31: #N/A | X31: Yes | Y31: Yes | Z31: Yes | AA31: Yes | AB31: Yes | AC31: Yes | AD31: No | AE31: No | AF31: No | AG31: No | AH31: No | AI31: No | AJ31: No | AK31: No
A32: 31 | B32: PP00018 | C32: SBM Rural UP | J32: =VLOOKUP(Table1[[#This Row],[Project Code]],'[6]Combined Nov''25'!$E:$O,10,FALSE) -> #N/A | K32: Department of Panchayati Raj | L32: Government of Uttar Pradesh | M32: State Govt. | N32: =VLOOKUP(Table1[[#This Row],[Project Code]],'[6]Combined Nov''25'!$E:$K,7,FALSE) -> #N/A | O32: Water & Sanitation | P32: Uttar Pradesh | Q32: TPI/TPA/TPE/TPQA | T32: =VLOOKUP(Table1[[#This Row],[Project Code]],'[6]Combined Nov''25'!$E:$P,12,FALSE) -> #N/A | U32: #N/A | V32: #N/A | W32: #N/A | X32: Yes | Y32: Yes | Z32: Yes | AA32: No | AB32: Yes | AC32: Yes | AD32: Yes | AE32: No | AF32: No | AG32: No | AH32: No | AI32: No | AJ32: No | AK32: No
A33: 32 | B33: PP00019 | C33: Swachh NDMC | J33: =VLOOKUP(Table1[[#This Row],[Project Code]],'[6]Combined Nov''25'!$E:$O,10,FALSE) -> #N/A | K33: New Delhi Municipal Council | L33: Government of NCT of Delhi | M33: State Govt. | N33: =VLOOKUP(Table1[[#This Row],[Project Code]],'[6]Combined Nov''25'!$E:$K,7,FALSE) -> #N/A | O33: Water & Sanitation | P33: NCT of Delhi | Q33: TPI/TPA/TPE/TPQA | T33: =VLOOKUP(Table1[[#This Row],[Project Code]],'[6]Combined Nov''25'!$E:$P,12,FALSE) -> #N/A | U33: #N/A | V33: #N/A | W33: #N/A | X33: Yes | Y33: No | Z33: Yes | AA33: Yes | AB33: Yes | AC33: Yes | AD33: No | AE33: No | AF33: No | AG33: No | AH33: No | AI33: No | AJ33: No | AK33: No
A34: 33 | B34: PP00020 | C34: ALF Swachhta Award Ranking | J34: =VLOOKUP(Table1[[#This Row],[Project Code]],'[6]Combined Nov''25'!$E:$O,10,FALSE) -> #N/A | K34: =VLOOKUP(Table1[[#This Row],[Project Code]],'[6]Combined Nov''25'!$E:$K,6,FALSE) -> #N/A | L34: Ministry of Housing and Urban Affairs | M34: Ministry | N34: =VLOOKUP(Table1[[#This Row],[Project Code]],'[6]Combined Nov''25'!$E:$K,7,FALSE) -> #N/A | O34: Governanace, Administration & Digital Infrastructure | P34: Pan India | Q34: Capacity building & Impact Assessment | T34: =VLOOKUP(Table1[[#This Row],[Project Code]],'[6]Combined Nov''25'!$E:$P,12,FALSE) -> #N/A | U34: #N/A | V34: #N/A | W34: #N/A | X34: Yes | Y34: Yes | Z34: Yes | AA34: No | AB34: Yes | AC34: Yes | AD34: No | AE34: No | AF34: No | AG34: No | AH34: No | AI34: No | AJ34: No | AK34: No
A35: 34 | B35: PP00021 | C35: Power Urban | J35: =VLOOKUP(Table1[[#This Row],[Project Code]],'[6]Combined Nov''25'!$E:$O,10,FALSE) -> #N/A | K35: =VLOOKUP(Table1[[#This Row],[Project Code]],'[6]Combined Nov''25'!$E:$K,6,FALSE) -> #N/A | L35: Ministry of Power | M35: Ministry | N35: =VLOOKUP(Table1[[#This Row],[Project Code]],'[6]Combined Nov''25'!$E:$K,7,FALSE) -> #N/A | O35: Structural & Utilities Management | P35: Pan India | Q35: TPI/TPA/TPE/TPQA | T35: =VLOOKUP(Table1[[#This Row],[Project Code]],'[6]Combined Nov''25'!$E:$P,12,FALSE) -> #N/A | U35: #N/A | V35: #N/A | W35: #N/A | X35: Yes | Y35: Yes | Z35: Yes | AA35: No | AB35: Yes | AC35: Yes | AD35: Yes | AE35: No | AF35: No | AG35: No | AH35: No | AI35: No | AJ35: No | AK35: No
A36: 35 | B36: PP00022 | C36: Power Rural 2018 | J36: =VLOOKUP(Table1[[#This Row],[Project Code]],'[6]Combined Nov''25'!$E:$O,10,FALSE) -> #N/A | K36: =VLOOKUP(Table1[[#This Row],[Project Code]],'[6]Combined Nov''25'!$E:$K,6,FALSE) -> #N/A | L36: Ministry of Power | M36: Ministry | N36: =VLOOKUP(Table1[[#This Row],[Project Code]],'[6]Combined Nov''25'!$E:$K,7,FALSE) -> #N/A | O36: Structural & Utilities Management | P36: Pan India | Q36: TPI/TPA/TPE/TPQA | T36: =VLOOKUP(Table1[[#This Row],[Project Code]],'[6]Combined Nov''25'!$E:$P,12,FALSE) -> #N/A | U36: #N/A | V36: #N/A | W36: #N/A | X36: No | Y36: No | Z36: No | AA36: No | AB36: No | AC36: No | AD36: No | AE36: No | AF36: No | AG36: No | AH36: No | AI36: No | AJ36: No | AK36: No
A37: 36 | B37: PP00023 | C37: MoPNG - PMU | J37: =VLOOKUP(Table1[[#This Row],[Project Code]],'[6]Combined Nov''25'!$E:$O,10,FALSE) -> #N/A | K37: =VLOOKUP(Table1[[#This Row],[Project Code]],'[6]Combined Nov''25'!$E:$K,6,FALSE) -> #N/A | L37: Ministry of Petroleum and Natural Gas | M37: Ministry | N37: =VLOOKUP(Table1[[#This Row],[Project Code]],'[6]Combined Nov''25'!$E:$K,7,FALSE) -> #N/A | O37: Governanace, Administration & Digital Infrastructure | P37: Pan India | Q37: PMU/PMC | T37: =VLOOKUP(Table1[[#This Row],[Project Code]],'[6]Combined Nov''25'!$E:$P,12,FALSE) -> #N/A | U37: #N/A | V37: #N/A | W37: #N/A | X37: Yes | Y37: Yes | Z37: Yes | AA37: No | AB37: Yes | AC37: Yes | AD37: Yes | AE37: No | AF37: No | AG37: No | AH37: No | AI37: No | AJ37: No | AK37: No
A38: 37 | B38: PP00024 | C38: DARPG- Citizen's Charter | J38: =VLOOKUP(Table1[[#This Row],[Project Code]],'[6]Combined Nov''25'!$E:$O,10,FALSE) -> #N/A | K38: =VLOOKUP(Table1[[#This Row],[Project Code]],'[6]Combined Nov''25'!$E:$K,6,FALSE) -> #N/A | L38: Department of Administrative Reforms and Public Grievances | M38: Ministry | N38: =VLOOKUP(Table1[[#This Row],[Project Code]],'[6]Combined Nov''25'!$E:$K,7,FALSE) -> #N/A | O38: Governanace, Administration & Digital Infrastructure | P38: Pan India | Q38: Capacity building & Impact Assessment | T38: =VLOOKUP(Table1[[#This Row],[Project Code]],'[6]Combined Nov''25'!$E:$P,12,FALSE) -> #N/A | U38: #N/A | V38: #N/A | W38: #N/A | X38: Yes | Y38: No | Z38: No | AA38: No | AB38: No | AC38: No | AD38: No | AE38: No | AF38: No | AG38: No | AH38: No | AI38: No | AJ38: No | AK38: No
A39: 38 | B39: PP00025 | C39: DARPG- eOffice | J39: =VLOOKUP(Table1[[#This Row],[Project Code]],'[6]Combined Nov''25'!$E:$O,10,FALSE) -> #N/A | K39: =VLOOKUP(Table1[[#This Row],[Project Code]],'[6]Combined Nov''25'!$E:$K,6,FALSE) -> #N/A | L39: Department of Administrative Reforms and Public Grievances | M39: Ministry | N39: =VLOOKUP(Table1[[#This Row],[Project Code]],'[6]Combined Nov''25'!$E:$K,7,FALSE) -> #N/A | O39: Governanace, Administration & Digital Infrastructure | P39: Pan India | Q39: PMU/PMC | T39: =VLOOKUP(Table1[[#This Row],[Project Code]],'[6]Combined Nov''25'!$E:$P,12,FALSE) -> #N/A | U39: #N/A | V39: #N/A | W39: #N/A | X39: No | Y39: No | Z39: No | AA39: No | AB39: No | AC39: No | AD39: No | AE39: No | AF39: No | AG39: No | AH39: No | AI39: No | AJ39: No | AK39: No
A40: 39 | B40: PP00026 | C40: DARPG - Dashboard Extension | J40: =VLOOKUP(Table1[[#This Row],[Project Code]],'[6]Combined Nov''25'!$E:$O,10,FALSE) -> #N/A | K40: =VLOOKUP(Table1[[#This Row],[Project Code]],'[6]Combined Nov''25'!$E:$K,6,FALSE) -> #N/A | L40: Department of Administrative Reforms and Public Grievances | M40: Ministry | N40: =VLOOKUP(Table1[[#This Row],[Project Code]],'[6]Combined Nov''25'!$E:$K,7,FALSE) -> #N/A | O40: Governanace, Administration & Digital Infrastructure | P40: Pan India | Q40: Capacity building & Impact Assessment | T40: =VLOOKUP(Table1[[#This Row],[Project Code]],'[6]Combined Nov''25'!$E:$P,12,FALSE) -> #N/A | U40: #N/A | V40: #N/A | W40: #N/A | X40: No | Y40: Yes | Z40: Yes | AA40: No | AB40: Yes | AC40: Yes | AD40: No | AE40: No | AF40: No | AG40: No | AH40: No | AI40: No | AJ40: No | AK40: No
...

Sheet Sheet1

Sheet Sheet2
A1: Project Name | B1: Project Code | C1: State | D1: Client/Department | E1: Client/Ministry | F1: Client Type | G1: Sector/Domain (2) | H1: Nature of Project
A2: Confidential | B2: PB00001 | C2: Pan India | F2: Ministry | G2: Others | H2: Others
A3: Census of Traders | B3: PB00002 | C3: Pan India | D3: Department for Promotion of Industry and Internal Trade, | E3: Ministry of Commerce and Industry | F3: Ministry | G3: Financial Mgmt, Policy Analysis & Research | H3: Capacity building & Impact Assessment
A4: Confidential | B4: PB00003 | C4: Pan India | F4: Ministry | G4: Others | H4: Others
A5: TPI of buses, depots, workshops & stations of UP | B5: PB00004 | C5: Uttar Pradesh | D5: Uttar Pradesh State Road Transport Corporation (UPSRTC) | E5: Government of Uttar Pradesh | G5: Structural & Utilities Management | H5: TPI/TPA/TPE/TPQA
A6: Sarpanch Samvaad | B6: PB00011 | C6: Pan India | G6: Social Welfare, Education & Skill Development | H6: Capacity building & Impact Assessment
A7: Quality City Initiative (Nashik) | B7: PB00012 | C7: Maharashtra | D7: Nashik Municipal Corporation | E7: Government of Maharashtra | F7: State Govt. | G7: Water & Sanitation | H7: Others
A8: Trade Surveillance- Leather | B8: PB00013 | C8: Pan India | G8: Agriculture, Food Processing & Supply Chain | H8: TPI/TPA/TPE/TPQA
A9: Quality Assessment of Biogas | B9: PB00014 | C9: Gujarat | D9: Banaskantha District Co-op. Milk Producers' Union Ltd. | E9: Cooperative | F9: Cooperative | G9: Mining & Metallurgy | H9: TPI/TPA/TPE/TPQA
A10: Dipstick Assessment for receipt of free grains under PMGKAY | B10: PB00015 | C10: Pan India | E10: Department of Food and Public Distribution | F10: Ministry | G10: Agriculture, Food Processing & Supply Chain | H10: TPI/TPA/TPE/TPQA
A11: TPI of residential building under Rajasthan Housing Board | B11: PB00016 | C11: Rajasthan | G11: Structural & Utilities Management | H11: TPI/TPA/TPE/TPQA
A12: Social Impact Evaluation of the Projects Undertaken by Sasakawa – India Leprosy Foundation | B12: PB00017 | C12: Pan India | E12: Sasakawa-India Leprosy Foundation. | F12: Non-Profit Organisation | G12: Social Welfare, Education & Skill Development | H12: Capacity building & Impact Assessment
A13: Culture_National Library_2024 | B13: PB00018 | C13: Pan India | E13: Ministry of Culture | F13: Ministry | G13: Arts, Culture & Tourism | H13: Capacity building & Impact Assessment
A14: Assessment, Capacity Building & Certification of Shri Somnath Trust | B14: PB00019 | C14: Gujarat | E14: Shri Somnath Trust | F14: Independent Body | G14: Arts, Culture & Tourism | H14: Capacity building & Impact Assessment
A15: Third Party Sampling, Testing and Analysis of Coal | B15: PP00001 | C15: Pan India | E15: Coal India Limited | F15: PSU | G15: Mining & Metallurgy | H15: TPI/TPA/TPE/TPQA
A16: ODF Verification under SBM Urban | B16: PP00002 | C16: Pan India | E16: Ministry of Housing and Urban Affairs | F16: Ministry | G16: Water & Sanitation | H16: TPI/TPA/TPE/TPQA
A17: MoUD Star Rating - Garbage Free Cities | B17: PP00003 | C17: Pan India | E17: Ministry of Housing and Urban Affairs | F17: Ministry | G17: Water & Sanitation | H17: TPI/TPA/TPE/TPQA
A18: TPI of SWM Status of 97 Ganga Towns | B18: PP00004 | C18: Pan India | E18: Ministry of Housing and Urban Affairs | F18: Ministry | G18: Water & Sanitation | H18: TPI/TPA/TPE/TPQA
A19: India Development Foundation of Overseas Indians Assessment | B19: PP00005 | C19: Pan India | D19: IBF-OI | E19: Govt Body (Not for Profit) | F19: Ministry | G19: Financial Mgmt, Policy Analysis & Research | H19: TPI/TPA/TPE/TPQA
A20: Swachh Survekshan in HPCL Retail Outlets | B20: PP00006 | C20: Pan India | E20: HPCL | F20: PSU | G20: Water & Sanitation | H20: TPI/TPA/TPE/TPQA
A21: Assisting & Capacity Building of 51 ULB's of Madhya Pradesh for Swachh Survekshan 2019 | B21: PP00007 | C21: Madhya Pradesh | E21: Government of Madhya Pradesh | F21: State Govt. | G21: Water & Sanitation | H21: Capacity building & Impact Assessment
A22: Capacity Building at Gwalior Municipal Corporation for Swachh Survekshan 2019 | B22: PP00008 | C22: Madhya Pradesh | D22: Municipal Corporation of Gwalior | E22: Government of Madhya Pradesh | F22: State Govt. | G22: Water & Sanitation | H22: Capacity building & Impact Assessment
A23: Swachh Pradesh Swastha Pradesh, MP -SBM Urban | B23: PP00009 | C23: Madhya Pradesh | E23: Government of Madhya Pradesh | F23: State Govt. | G23: Water & Sanitation | H23: TPI/TPA/TPE/TPQA
A24: Independant Cleanliness of Public Toilets in Delhi | B24: PP00010 | C24: NCT of Delhi | E24: Ministry of Housing and Urban Affairs | F24: Ministry | G24: Water & Sanitation | H24: TPI/TPA/TPE/TPQA
A25: Google Toilet Mapping- SBM Urban | B25: PP00011 | C25: Pan India | E25: Ministry of Housing and Urban Affairs | F25: Ministry | G25: Water & Sanitation | H25: TPI/TPA/TPE/TPQA
A26: Third Party Verification Agency for District Level Verified ODF Gram Panchayats under SBM | B26: PP00012 | C26: Jharkhand | E26: Government of Jharkhand | F26: State Govt. | G26: Water & Sanitation | H26: TPI/TPA/TPE/TPQA
A27: TPA of Railway Stations, Ministry of Railways | B27: PP00013 | C27: Pan India | E27: Ministry of Railways | F27: Ministry | G27: Water & Sanitation | H27: TPI/TPA/TPE/TPQA
A28: Swachh Survekshan Telangana | B28: PP00014 | C28: Telangana | E28: Government of Telangana | F28: State Govt. | G28: Water & Sanitation | H28: TPI/TPA/TPE/TPQA
A29: TPA for High-End Cleaning Assessment at Gujarat Yatradhams | B29: PP00015 | C29: Gujarat | D29: Tourism Corporation of Gujarat Limited | E29: Government of Gujarat | F29: State Govt. | G29: Water & Sanitation | H29: TPI/TPA/TPE/TPQA
A30: TPI of Cleanliness Project by TCGL | B30: PP00016 | C30: Gujarat | D30: Tourism Corporation of Gujarat Limited | E30: Government of Gujarat | F30: State Govt. | G30: Water & Sanitation | H30: TPI/TPA/TPE/TPQA
A31: TPA for High-End Cleaning at Statue of Unity, TCGL | B31: PP00017 | C31: Gujarat | D31: Tourism Corporation of Gujarat Limited | E31: Government of Gujarat | F31: State Govt. | G31: Structural & Utilities Management | H31: TPI/TPA/TPE/TPQA
A32: TPV of ODF Villages under SBM Rural, PRD, Govt of UP | B32: PP00018 | C32: Uttar Pradesh | D32: Department of Panchayati Raj | E32: Government of Uttar Pradesh | F32: State Govt. | G32: Water & Sanitation | H32: TPI/TPA/TPE/TPQA
A33: Assessment of NDMC Preparedness for SS 2019 | B33: PP00019 | C33: NCT of Delhi | D33: New Delhi Municipal Council | E33: Government of NCT of Delhi | F33: State Govt. | G33: Water & Sanitation | H33: TPI/TPA/TPE/TPQA
A34: ALF Swachhta Awards 2019, DAY NULM | B34: PP00020 | C34: Pan India | E34: Ministry of Housing and Urban Affairs | F34: Ministry | G34: Governanace, Administration & Digital Infrastructure | H34: Capacity building & Impact Assessment
A35: Quality Assessment of RAPDRP | B35: PP00021 | C35: Pan India | E35: Ministry of Power | F35: Ministry | G35: Structural & Utilities Management | H35: TPI/TPA/TPE/TPQA
A36: Quality Assessment of Rural Electrification under DDUGKY | B36: PP00022 | C36: Pan India | E36: Ministry of Power | F36: Ministry | G36: Structural & Utilities Management | H36: TPI/TPA/TPE/TPQA
A37: MoPNG - PMU | B37: PP00023 | C37: Pan India | E37: Ministry of Petroleum and Natural Gas | F37: Ministry | G37: Governanace, Administration & Digital Infrastructure | H37: PMU/PMC
A38: Citizen's Charter Enhancement, Department of Administrative Reforms and Public Grievances | B38: PP00024 | C38: Pan India | E38: Department of Administrative Reforms and Public Grievances | F38: Ministry | G38: Governanace, Administration & Digital Infrastructure | H38: Capacity building & Impact Assessment
A39: EOffice Implementation PMU, Department of Administrative Reforms and Public Grievances | B39: PP00025 | C39: Pan India | E39: Department of Administrative Reforms and Public Grievances | F39: Ministry | G39: Governanace, Administration & Digital Infrastructure | H39: PMU/PMC
A40: Department of Administrative Reforms and Public Grievances Dashboard | B40: PP00026 | C40: Pan India | E40: Department of Administrative Reforms and Public Grievances | F40: Ministry | G40: Governanace, Administration & Digital Infrastructure | H40: Capacity building & Impact Assessment
...
